<?xml version="1.0"?>
<robot name="turtlebot_hardware" xmlns:xacro="http://ros.org/wiki/xacro">

  <include filename="$(find tb_description)/urdf/gazebo.urdf.xacro"/>
  <include filename="$(find tb_description)/urdf/turtlebot_calibration.xacro" />

<xacro:macro name="turtlebot_kinect">
  <joint name="kinect_joint" type="revolute">
 
    <!--limit upper="1.57" lower="-1.57" velocity="1.0" effort="1.0"/-->
    <axis xyz="0 1 0"/>
    
    <!-- From -45 to 90 degrees -->
    <limit  lower="${-M_PI/2}" upper="${M_PI/2}" effort="300" velocity="1.17" />
    <!--dynamics damping="50" friction="1"/-->
    <!--safety_controller k_position="0" k_velocity="0" soft_lower_limit="0" soft_upper_limit="0" /-->

    <origin xyz="${turtlebot_calib_cam_x} ${turtlebot_calib_cam_y} ${turtlebot_calib_cam_z}" 
            rpy="${turtlebot_calib_cam_rr} ${turtlebot_calib_cam_rp} ${turtlebot_calib_cam_ry}" />
    <parent link="${turtlebot_camera_parent_name}" />
    <child link="camera_link" />
  </joint>

  <link name="camera_link">
    <inertial>
      <mass value="0.01" />
      <origin xyz="0 0 0" />
      <inertia ixx="0.001" ixy="0.0" ixz="0.0"
        iyy="0.001" iyz="0.0"
        izz="0.001" />
    </inertial>

    <visual>
      <origin xyz=" 0 0 0 " rpy="0 0 0" />
      <geometry>
        <mesh filename="package://btb_description/meshes/kinect.dae"/>
      </geometry>
    </visual>

    <collision>
      <origin xyz="0.0 0.0 0.0" rpy="0 0 0" />
      <geometry>
        <box size="0.0730 .2760 0.0720"/>
      </geometry>
    </collision>

  </link>

  <joint name="camera_depth_joint" type="fixed">
    <origin xyz="0 0.018 0" rpy="0 0 0" />
    <parent link="camera_link" />
    <child link="camera_depth_frame" />
  </joint>

  <link name="camera_depth_frame">
    <inertial>
      <mass value="0.01" />
      <origin xyz="0 0 0" />
      <inertia ixx="0.001" ixy="0.0" ixz="0.0"
        iyy="0.001" iyz="0.0"
        izz="0.001" />
    </inertial>
  </link>

  <joint name="camera_depth_optical_joint" type="fixed">
    <origin xyz="0 0 0" rpy="${-M_PI/2} 0 ${-M_PI/2}" />
    <parent link="camera_depth_frame" />
    <child link="camera_depth_optical_frame" />
  </joint>

  <link name="camera_depth_optical_frame">
    <inertial>
      <mass value="0.001" />
      <origin xyz="0 0 0" />
      <inertia ixx="0.0001" ixy="0.0" ixz="0.0"
        iyy="0.0001" iyz="0.0"
        izz="0.0001" />
    </inertial>
  </link>

  <joint name="camera_rgb_joint" type="fixed">
    <origin xyz="0 -0.005 0" rpy="0 0 0" />
    <parent link="camera_link" />
    <child link="camera_rgb_frame" />
  </joint>

  <link name="camera_rgb_frame">
    <inertial>
      <mass value="0.001" />
      <origin xyz="0 0 0" />
      <inertia ixx="0.0001" ixy="0.0" ixz="0.0"
        iyy="0.0001" iyz="0.0"
        izz="0.0001" />
    </inertial>
  </link>

  <joint name="camera_rgb_optical_joint" type="fixed">
    <origin xyz="0 0 0" rpy="${-M_PI/2} 0 ${-M_PI/2}" />
    <parent link="camera_rgb_frame" />
    <child link="camera_rgb_optical_frame" />
  </joint>

  <link name="camera_rgb_optical_frame">
    <inertial>
      <mass value="0.001" />
      <origin xyz="0 0 0" />
      <inertia ixx="0.0001" ixy="0.0" ixz="0.0"
        iyy="0.0001" iyz="0.0"
        izz="0.0001" />
    </inertial>
  </link>
  
  <gazebo reference="kinect_joint">
    <erp>0.8</erp>
    <!--stopKd value="1.0" /-->
    <stopKd value="1000000.0" />
    <stopKp value="1000000.0" />
    <fudgeFactor value="0.5" />
  </gazebo>
  
  <gazebo reference="camera_link">
    <selfCollide>true</selfCollide>
    <turnGravityOff>true</turnGravityOff>
  </gazebo>
  
  <gazebo reference="camera_depth_frame">
    <selfCollide>true</selfCollide>
    <turnGravityOff>true</turnGravityOff>
  </gazebo>
  
  <gazebo reference="camera_depth_optical_frame">
    <selfCollide>true</selfCollide>
    <turnGravityOff>true</turnGravityOff>
  </gazebo>
  
  <gazebo reference="camera_rgb_frame">
    <selfCollide>true</selfCollide>
    <turnGravityOff>true</turnGravityOff>
  </gazebo>
  
  <gazebo reference="camera_rgb_optical_frame">
    <selfCollide>true</selfCollide>
    <turnGravityOff>true</turnGravityOff>
  </gazebo>

  <!-- Kinect sensor for simulation -->
  <turtlebot_sim_kinect/>
  
</xacro:macro>

</robot>
