<?xml version="1.0"?>
<robot name="turtlebot_hardware" xmlns:xacro="http://ros.org/wiki/xacro">
  <property name="M_PI" value="3.14159"/>

  <!-- Macro for TurtleBot body. Including Gazebo extensions, but does not include Kinect -->
  <xacro:include filename="$(find tb_description)/urdf/gazebo.urdf.xacro"/>


  <property name="base_x" value="0.33" />
  <property name="base_y" value="0.33" />


  <xacro:macro name="turtlebot_body">
    <material name="GreenTB">
      <color rgba="0.0 0.8 0.0 1.0"/>
    </material>

  <!-- base_footprint is a fictitious link(frame) that is on the ground right below base_link origin, navigation stack depends on this frame -->

  <link name="base_footprint">
    <inertial>
      <mass value="0.0001" />
      <origin xyz="0 0 0" />
      <inertia ixx="0.0001" ixy="0.0" ixz="0.0"
              iyy="0.0001" iyz="0.0" 
              izz="0.0001" />
    </inertial>

    <visual>
      <origin xyz="0 0 0" rpy="0 0 0" />
      <geometry>
        <box size="0.001 0.001 0.001" />
      </geometry>
      <material name="GreenTB" />
    </visual>

    <collision>
      <origin xyz="0 0 0.017" rpy="0 0 0" />
      <geometry>
       <box size="0.001 0.001 0.001" />
      </geometry>
    </collision>
  </link>

  <link name="base_link">
    <inertial>
      <mass value="10.0" />
      <origin xyz="0 0 0.0" />
      <inertia ixx="0.01" ixy="0.0" ixz="0.0"
        iyy="0.01" iyz="0.0" izz="0.5" />
    </inertial>

    <visual>
      <origin xyz=" 0 0 0.0308" rpy="0 0 0" />
      <geometry>
        <mesh filename="package://create_description/meshes/create_body.dae"/>
      </geometry>
    </visual>

    <collision>
      <origin xyz="0.0 0.0 0.0308" rpy="0 0 0" />
      <geometry>
        <cylinder length="0.0611632" radius="0.016495"/>
      </geometry>
    </collision>
  </link>

 

  <joint name="base_footprint_joint" type="fixed">
    <origin xyz="0 0 0.017" rpy="0 0 0" />        
    <parent link="base_footprint"/>
    <child link="base_link" />
  </joint>
  
  
   <joint name="tb_back_joint" type="fixed">
    <origin xyz="-0.125 0 0.5" rpy="0 0 0" />
    <parent link="base_link" />
    <child link="tb_back_link" />
  </joint>

  <link name="tb_back_link">
    <inertial>
      <mass value="0.8" />
      <origin xyz="0 0 0" rpy="0 0 0" />
      <inertia ixx="0.001" ixy="0.0" ixz="0.0"
        iyy="0.001" iyz="0.0"
        izz="0.001" />
    </inertial>

    <visual>
      <origin xyz=" 0 0 0 " rpy="0 0 0" />
      <geometry>
        <box size="0.05 .23 0.95"/>
      </geometry>
      <material name="blue">
        <color rgba="0 0 .8 1"/>
      </material>
    </visual>

    <collision>
      <origin xyz="0.0 0.0 0.0" rpy="0 0 0" />
      <geometry>
        <box size="0.05 .23 0.9"/>
      </geometry>
    </collision>

  </link>
  
  <gazebo reference="tb_back_link">
    <material value="Gazebo/Blue" />
  </gazebo>
  
  <joint name="tb_camera_support_joint" type="fixed">
    <origin xyz="-0.125 0 0.5" rpy="0 0 0" />
    <parent link="base_link" />
    <child link="tb_camera_support_link" />
  </joint>
  
    <link name="tb_camera_support_link">
    <inertial>
      <mass value="0.1" />
      <origin xyz="0.1 0 0" rpy="0 0 0" />
      <inertia ixx="0.001" ixy="0.0" ixz="0.0"
        iyy="0.001" iyz="0.0"
        izz="0.001" />
    </inertial>

    <visual>
      <origin xyz="0.1 0 0 " rpy="0 0 0" />
      <geometry>
        <box size="0.2 0.2 0.03"/>
      </geometry>
      <material name="blue">
        <color rgba="0 0 .8 1"/>
      </material>
    </visual>

    <collision>
      <origin xyz="0.1 0.0 0.0" rpy="0 0 0" />
      <geometry>
        <box size="0.2 0.2 0.03"/>
      </geometry>
    </collision>

  </link>
  
  <gazebo reference="tb_camera_support_link">
    <material value="Gazebo/Blue" />
  </gazebo>
  
    <joint name="tb_ntb_joint" type="fixed">
    <origin xyz="0.03 0 0.075" rpy="0 0 0" />
    <parent link="base_link" />
    <child link="tb_ntb_link" />
  </joint>
  
    <link name="tb_ntb_link">
    <inertial>
      <mass value="3.0" />
      <origin xyz="0 0 0" rpy="0 0 0" />
      <inertia ixx="0.001" ixy="0.0" ixz="0.0"
        iyy="0.001" iyz="0.0"
        izz="0.001" />
    </inertial>

    <visual>
      <origin xyz="0 0 0 " rpy="0 0 0" />
      <geometry>
        <box size="0.25 0.4 0.03"/>
      </geometry>
      <material name="grey">
        <color rgba="0.6 0.6 0.6 1"/>
      </material>
    </visual>

    <collision>
      <origin xyz="0 0.0 0.0" rpy="0 0 0" />
      <geometry>
        <box size="0.25 0.4 0.03"/>
      </geometry>
    </collision>

  </link>
  
    <gazebo reference="tb_ntb_link">
    <material value="Gazebo/Grey" />
  </gazebo>


  <link name="left_wheel_link">
    <inertial>
      <origin xyz="0 0 0"/>
      <mass value="0.01" />
      <inertia ixx="0.001" ixy="0.0" ixz="0.0"
        iyy="0.001" iyz="0.0" izz="0.001" />
    </inertial>

    <visual>
      <origin xyz="0 0 0" rpy="0 ${M_PI/2} ${M_PI/2}" />
      <geometry>
        <cylinder radius="0.033" length = "0.023"/>
      </geometry>
    </visual>

    <collision>
      <origin xyz="0 0 0" rpy="0 ${M_PI/2} ${M_PI/2}" />
      <geometry>
        <cylinder radius="0.033" length = "0.023"/>
      </geometry>
    </collision>
  </link>

  <joint name="left_wheel_joint" type="continuous">
    <origin xyz="0 0.13 0.015" rpy="0 0 0"/>
    <parent link="base_link"/>
    <child link="left_wheel_link"/>
    <axis xyz="0 1 0"/>
    <anchor xyz="0 0 0" />
    <limit effort="100" velocity="100" />
    <!--joint_properties damping="0.0" friction="0.0" /-->
  </joint>

  <link name="right_wheel_link">
    <inertial>
      <origin xyz="0 0 0"/>
      <mass value="0.01" />
      <inertia ixx="0.001" ixy="0.0" ixz="0.0"
        iyy="0.001" iyz="0.0" izz="0.001" />
    </inertial>

    <visual>
      <origin xyz="0 0 0" rpy="0 ${M_PI/2} ${M_PI/2}" />
      <geometry>
        <cylinder radius="0.033" length = "0.023"/>
      </geometry>
    </visual>

    <collision>
      <origin xyz="0 0 0" rpy="0 ${M_PI/2} ${M_PI/2}" />
      <geometry>
        <cylinder radius="0.033" length = "0.023"/>
      </geometry>
    </collision>
  </link>

  <joint name="right_wheel_joint" type="continuous">
    <origin xyz="0 -0.13 0.015" rpy="0 0 0"/>
    <parent link="base_link"/>
    <child link="right_wheel_link"/>
    <axis xyz="0 1 0"/>
    <anchor xyz="0 0 0" />
    <limit effort="100" velocity="100" />
    <!--dynamics damping="0.0" friction="0.0" /-->
  </joint>
  
  
  

  <link name="rear_wheel_link">
    <inertial>
      <origin xyz="0 0 0"/>
      <mass value="0.001" />
      <inertia ixx="0.0001" ixy="0.0" ixz="0.0"
        iyy="0.0001" iyz="0.0" izz="0.0001" />
    </inertial>

    <visual>
      <origin xyz="0 0 0" rpy="0 ${M_PI/2} ${M_PI/2}"/>
      <geometry>
        <sphere radius="0.015" />
      </geometry>
    </visual>

    <collision>
      <origin xyz="0 0 0" rpy="0 ${M_PI/2} ${M_PI/2}" />
      <geometry>
        <sphere radius="0.015" />
      </geometry>
    </collision>
  </link>
  <!-- fixed because there's no transmission -->
  <joint name="rear_castor_joint" type="fixed">
    <origin xyz="-0.13 0 0.0" rpy="0 0 0"/>
    <parent link="base_link"/>
    <child link="rear_wheel_link"/>
    <axis xyz="0 1 0"/>
  </joint>

  <link name="front_wheel_link">
    <inertial>
      <origin xyz="0 0 0" />
      <mass value="0.01" />
      <inertia ixx="0.001" ixy="0.0" ixz="0.0"
        iyy="0.001" iyz="0.0" izz="0.001" />
    </inertial>

    <visual>
      <origin xyz="0 0 0" rpy="0 ${M_PI/2} ${M_PI/2}"/>
      <geometry>
        <sphere radius="0.018" />
      </geometry>
    </visual>

    <collision>
      <origin xyz="0 0 0" rpy="0 ${M_PI/2} ${M_PI/2}" />
      <geometry>
        <sphere radius="0.018" />
      </geometry>
    </collision>
  </link>

  <!-- fixed because there's no transmission -->
  <joint name="front_castor_joint" type="fixed">
    <origin xyz="0.13 0 0.0" rpy="0 0 0"/>
    <parent link="base_link"/>
    <child link="front_wheel_link"/>
    <axis xyz="0 1 0"/>
  </joint>

  <joint name="imu_left_joint" type="fixed">
    <origin xyz="-0.13 0.09 0" rpy="0 0 0" />
    <parent link="base_link"/>
    <child link="imu_left_link"/>
  </joint>
  
  <link name="imu_left_link">
    <inertial>
      <mass value="0.001" />
      <origin xyz="0 0 0" rpy="0 0 0" />
      <inertia ixx="0.0001" ixy="0" ixz="0" iyy="0.000001" iyz="0" izz="0.0001" />
    </inertial>
  </link>
  
  <joint name="imu_right_joint" type="fixed">
    <origin xyz="-0.13 -0.09 0" rpy="0 0 0" />
    <parent link="base_link"/>
    <child link="imu_right_link"/>
  </joint>
  
  <link name="imu_right_link">
    <inertial>
      <mass value="0.001" />
      <origin xyz="0 0 0" rpy="0 0 0" />
      <inertia ixx="0.0001" ixy="0" ixz="0" iyy="0.000001" iyz="0" izz="0.0001" />
    </inertial>
  </link>

  <joint name="laser_joint" type="fixed">
  
    <!-- correct values for rpy are ${M_PI} 0 0 (real laser is upside down), but then gmapping doesn't work -->
    <origin xyz="0.26 0 0.025" rpy="0 0 0" />
    
    <parent link="base_link" />
    <child link="laser" />
  </joint>

  <link name="laser">

    <visual>
      <origin xyz="0 0 0.05" rpy="0 0 0" />
      <geometry>
        <box size="0.1 0.1 0.15" />
      </geometry>
      <material name="blue">
        <color rgba="0 0 .8 1"/>
      </material>
    </visual>
    
    <collision>
      <origin xyz="0 0 0.05" rpy="0 0 0" />
      <geometry>
        <box size="0.1 0.1 0.15" />
      </geometry>
    </collision>
    
    <inertial>
      <mass value="0.5" />
      <origin xyz="0 0 0.05" />
      <inertia ixx="0.0001" ixy="0.0" ixz="0.0"
        iyy="0.0001" iyz="0.0"
        izz="0.0001" />
    </inertial>
  </link>
  
  <gazebo reference="laser">
    <material value="Gazebo/Blue" />
  </gazebo>
  
  
    <link name="wall_sensor_link">
    <inertial>
      <mass value="0.01" />
      <origin xyz="0 0 0"/>
      <inertia ixx="0.001" ixy="0.0" ixz="0.0"
        iyy="0.001" iyz="0.0" izz="0.001" />
    </inertial>
  </link>


  <link name="left_cliff_sensor_link">
    <inertial>
      <mass value="0.01" />
      <origin xyz="0 0 0"/>
      <inertia ixx="0.001" ixy="0.0" ixz="0.0"
        iyy="0.001" iyz="0.0" izz="0.001" />
    </inertial>
  </link>

  <link name="right_cliff_sensor_link">
    <inertial>
      <mass value="0.01" />
      <origin xyz="0 0 0"/>
      <inertia ixx="0.001" ixy="0.0" ixz="0.0"
        iyy="0.001" iyz="0.0" izz="0.001" />
    </inertial>
  </link>



  <link name="leftfront_cliff_sensor_link">
    <inertial>
      <mass value="0.01" />
      <origin xyz="0 0 0"/>
      <inertia ixx="1.0" ixy="0.0" ixz="0.0"
        iyy="0.01" iyz="0.0" izz="0.01" />
    </inertial>
  </link>

  <link name="rightfront_cliff_sensor_link">
    <inertial>
      <mass value="0.01" />
      <origin xyz="0 0 0"/>
      <inertia ixx="0.001" ixy="0.0" ixz="0.0"
        iyy="0.001" iyz="0.0" izz="0.001" />
    </inertial>
  </link>

  <joint name="base_wall_sensor_joint" type="fixed">
    <origin xyz="0.09 -0.120 0.042" rpy="0 0 -1.0" />        
    <parent link="base_link"/>
    <child link="wall_sensor_link" />
  </joint>

  <joint name="base_left_cliff_sensor_joint" type="fixed">
    <origin xyz="0.07 0.14 0.01" rpy="0 ${M_PI/2} 0" />        
    <parent link="base_link"/>
    <child link="left_cliff_sensor_link" />
  </joint>

  <joint name="base_right_cliff_sensor_joint" type="fixed">
    <origin xyz="0.07 -0.14 0.01" rpy="0 ${M_PI/2} 0" />        
    <parent link="base_link"/>
    <child link="right_cliff_sensor_link" />
  </joint>

  <joint name="base_leftfront_cliff_sensor_joint" type="fixed">
    <origin xyz="0.15 0.04 0.01" rpy="0 ${M_PI/2} 0" />        
    <parent link="base_link"/>
    <child link="leftfront_cliff_sensor_link" />
  </joint>

  <joint name="base_rightfront_cliff_sensor_joint" type="fixed">
    <origin xyz="0.15 -0.04 0.01" rpy="0 ${M_PI/2} 0" />        
    <parent link="base_link"/>
    <child link="rightfront_cliff_sensor_link" />
  </joint>


  <!-- transmissions -->
  <transmission type="pr2_mechanism_model/SimpleTransmission" name="left_wheel_trans">
    <actuator name="left_wheel_motor" />
    <joint name="left_wheel_joint" />
    <mechanicalReduction>1.0</mechanicalReduction>
  </transmission>
  
  <transmission type="pr2_mechanism_model/SimpleTransmission" name="right_wheel_trans">
    <actuator name="right_wheel_motor" />
    <joint name="right_wheel_joint" />
    <mechanicalReduction>1.0</mechanicalReduction>
  </transmission>
  
  <gazebo reference="laser">
    <selfCollide>false</selfCollide>
    <turnGravityOff>false</turnGravityOff>
  </gazebo>
 
  
  <!-- Simulation sensors -->
  <turtlebot_sim_imu_left/>
  <!--<turtlebot_sim_imu_right/>-->
  <turtlebot_sim_laser/>
  <turtlebot_sim_create/>
  <turtlebot_sim_wall_sensors/>
  
  </xacro:macro>

</robot>
